Workbook

Sheet Sheet1
B1: MOHD. YAMIN
B2: Govt of India | G2: [Surveyor & Loss Assessor] | J2: 208-B,Rishabh corporate Tower
B3: Licence No.72970/23-2026 | H3: Marine Cargo, Fire, Motor, Misc. | J3: Karkardooma,New Delhi-110092
B4: Expiring on 23/08/2026 | J4: Mobile:9818430881
B5: PAN: ALVPM9337N | J5: Email:yamin.ae@gmail.com
B8: Report Ref No. | E8: MY/MOTOR/2025/ | J8: DATE:
H9: MOTOR SURVEY REPORT ( FINAL )
B11: This report is issued by me as a licensed surveyor without prejudice in respect of cause,nature and extent
B12: of loss/damage and subject to the terms and conditions of the insurance policy.
B14: Policy No.: | H14: Period: | L14: No.of Claims | O14: Estimate No.
B16: Claim No.: | D16: ----
B18: INSURERS | G18: : | H18: National Insurance Company Ltd.
H19: DO-1, Gurgaon , SCO 41-43 , Sector-31
H20: Haryana
B22: INSURED | G22: :
B26: HPA | G26: : | H26: None
B28: IDV | G28: : | H28: Rs
B30: VEHICLE PARTICULARS | H30: [RC checked from original]
B32: a) | C32: Vehicle Number | G32: :
B33: b) | C33: Chassis Number | G33: : | J33: [Physically Verified]
B34: c) | C34: Engine Number | G34: :
B35: d) | C35: Date of Registration | G35: :
B36: e) | C36: Make / Model | G36: :
B37: f) | C37: Road Tax upto | G37: : | H37: One Time Tax
B38: g) | C38: Class of Vehicle | G38: : | H38: LMV
B39: h) | C39: Seating Capacity | G39: : | H39: 5
B40: i) | C40: Permit No./ Valid upto | G40: : | H40: N/A
B41: j) | C41: Route/Area of Operation | G41: : | H41: N/A
B42: k) | C42: Fitness Cert.No./Valid upto | G42: : | H42: N/A
B43: l) | C43: Type of Body | G43: : | H43: Saloon
B44: m) | C44: R.L.W. | G44: : | H44: NA
B45: n) | C45: U.L.W. | G45: : | H45: NA
B46: o) | C46: Fuel Used | G46: : | H46: Petrol | L46: Check for CNG Kit Fittment
B47: p) | C47: KM Reading | G47: :
B49: DRIVER'S PARTICULARS | H49: [DL checked from original]
B50: a) | C50: Name of the Driver | G50: :
B51: b) | C51: Driving Licence Number | G51: :
B52: c) | C52: Date of Issue | G52: :
B53: d) | C53: Valid upto | G53: : | L53: Check Validity of Licence
B54: e) | C54: Issuing Authority | G54: :
...

Sheet Sheet2
B1: MOHD. YAMIN
B2: Govt of India | G2: [Surveyor & Loss Assessor] | J2: 208-B,Rishabh corporate Tower
B3: Licence No.72970/23-2026 | H3: Marine Cargo, Fire, Motor, Misc. | J3: Karkardooma,New Delhi-110092
B4: Expiring on 23/08/2026 | J4: Mobile:9818430881
J5: Email:yamin.ae@gmail.com
F7: SURVEY REPORT (RE-INSPECTION)
B9: Report Ref No. | E9: =Sheet1!E8 -> MY/MOTOR/2025/ | J9: DATE: | K9: =Sheet1!K8
B11: =Sheet1!B14 -> Policy No.: | D11: =Sheet1!#REF! -> #REF! | H11: Period: | I11: =Sheet1!I14 -> 0
B13: INSURERS | G13: : | H13: =Sheet1!H18 -> National Insurance Company Ltd.
H14: =Sheet1!H19 -> DO-1, Gurgaon , SCO 41-43 , Sector-31
H15: =Sheet1!H20 -> Haryana
B17: INSURED | G17: : | H17: =Sheet1!H22 -> 0
H18: =Sheet1!H23 -> 0
H19: =Sheet1!H24 -> 0
B21: VEHICLE PARTICULARS
B22: a) | C22: Registration No. | G22: : | H22: =Sheet1!H32 -> 0
B23: b) | C23: Chassis No. | G23: : | H23: =Sheet1!H33 -> 0 | I23: Physically Verified
B24: c) | C24: Engine No. | G24: : | H24: =Sheet1!H34 -> 0
B26: CLAIM NO.: | E26: =Sheet1!D16 -> ----
B28: OBSERVATIONS:
B33: a) | C33: The repairing work of the vehicle has been carried out satisfactorily.
B35: b) | C35: All the parts as allowed by me in Final Survey Report were found replaced with new & genuine one.
B37: c) | C37: The salvage was found in order & crushed.
C39: This report is issued without prejudice.
B44: ENCLOSURES:
B45: a) | C45: Digital Photographs | G45: : | H45: 5
B46: b) | C46: Survey fee bill | G46: : | H46: Yes
J52: [ MOHD. YAMIN ]
J53: SURVEYOR

Sheet Remarks
B4: The vehicle was re-inspected after repair and salvage was crushed.
B6: CNG kit fitted in the car and is endorsed in RC & Policy. | N6: FOR CNG Fitment
B8: Salvage value is NIL as salvage was crushed however Rs may be deducted towards | N8: For Fuel Tank Scrap Value
B9: scrap value of Fuel Tank .
B11: Pre-inspection Report & Photographs by Adroit Ref No. were checked before authorisation of repairs | N11: Pre-inspection available with Photos
B12: and only fresh damages were allowed for repair / replacement .
B14: This is insured 2nd claim and previous claim was surveyed by Mr .Photographs were checked | N14: Previous claim with Surveyor details & Photographs
B15: and only fresh damages were allowed for repair / replacement .
B17: Previous claim details were not available however damages seemed fresh and therfore allowed for | N17: Previous claim details not available
B18: repair / replacement .
B20: This is insured 2nd claim and previous claim was surveyed by Mr .Photographs were not provided | N20: Previous claim Surveyor details but No Photographs
B21: however damages seemed fresh and therfore allowed for repair / replacement .
B23: Nil Dep Policy and assessment has been done accordingly.
B25: Nil Dep Plus cover and assessment has been done accordingly and Rs has been reimbursed under ND Addon opted by insured in this policy
B27: Normal Indemnity policy and assessement has been done accordingly.
B29: Payment to be made in favour of Repairer.
B32: National Insurance Company Ltd.
B33: Scope Minar Core-3 , 2nd Floor , Laxmi Nagar
B34: New Delhi - 110092
B36: National Insurance Company Ltd.
B37: D.O.-4, Hero Vertical, 101-106, BMC House, Connaught Place
B38: New Delhi - 110 001
B40: National Insurance Company Ltd.
... B52: New Delhi

Sheet Sheet3
C3: Vehicle Number | E3: =Sheet1!H32 -> 0
C4: Insured | E4: =Sheet1!H22 -> 0
C5: Policy Number | E5: =Sheet1!#REF! -> #REF!
C6: Claim Number | E6: =Sheet1!K14 -> 0
D7: Claim Cost Approval Sheet
F11: Amount in RS
D12: 1 | E12: Parts allowed (@18%) after dep. without GST | F12: =2031.35+3844.06 -> 5875.41
D13: A- | E13: 18% GST on above | F13: =+F12*18% -> 1057.5738
D14: 2 | E14: Parts allowed (@28%) after dep. without GST | F14: =133.59+934.37+2734.37+1355.46+265.62 -> 5423.41 | J14: =16.9+97.45+84.74+312.71+73.72+18.22 -> 603.74 | K14: =17.55+23.4+10.15+71.87+71.87+32.03+34.38 -> 261.25
D15: B- | E15: 28% GST on above | F15: =+F14*28% -> 1518.5548 | J15: =+J14*18% -> 108.6732 | K15: =+K14*28% -> 73.15 | M15: =2472+2020+2020 -> 6512
D17: (1+2) | E17: Total of parts above WITHOUT GST | F17: =+F14+F12 -> 11298.82
E19: Labour without GST | F19: 450
E20: Painting Without GST | F20: 10744
E21: Total (Labour + Painting) without GST | F21: =+F20+F19 -> 11194
D22: C- | E22: 18% GST on (Labour + Paint) above | F22: =+F21*18% -> 2014.92
D24: (A+B+C) | E24: Total GST | F24: =+F13+F15+F22 -> 4591.0486
I25: =46.8+72.65 -> 119.45
E26: Add Towing | F26: 0 | I26: =+I25*28% -> 33.446
E27: Less Salvage | F27: 0
E28: Less Excess Clause | F28: 1000
E30: NET PAYABLE | F30: =+F24+F17-F28-F27+F26+F21 -> 26083.869

Sheet Claim cost Approval 
A3: Vehicle Number | C3: =Sheet1!H32 -> 0
A4: Insured Name | C4: =Sheet1!H22 -> 0
A5: Policy Number | C5: =Sheet1!D14 -> 0
A6: Claim Number | C6: =Sheet1!D16 -> ----
A8: Claim Cost Approval Sheet
C10: Metal | D10: Rubber | E10: Glass
B11: Parts allowed (@18%) without GST | C11: 0 | D11: 0 | E11: 0
B12: =CONCATENATE("Depreciation @ ",H12," %") -> Depreciation @ 25 % | C12: =C11*H12/100 -> 0 | H12: 25 | L12: 100
B13: Depreciation on Rubber @ 50 % | D13: =+D11*50% -> 0 | L13: =+L12*10% -> 10
B14: Depreciation on Glass @ 0 % | E14: 0
A15: 1 | B15: Amount After Depreciation | C15: =SUM(C11:E11)-C12-D13-E14 -> 0
A16: A- | B16: 18% GST on above | C16: =+C15*18% -> 0 | L16: =+L12-L13 -> 90
B18: Parts allowed (@28%) without GST | C18: 0 | D18: 0 | E18: 0 | L18: =+L16*18% -> 16.2
B19: =CONCATENATE("Depreciation @ ",H19," %") -> Depreciation @ 25 % | C19: =C18*H19/100 -> 0 | H19: 25
B20: Depreciation on Rubber @ 50 % | D20: =+D18*50% -> 0
B21: Depreciation on Glass @ 0 % | E21: 0
A22: 2 | B22: Amount After Depreciation | C22: =+SUM($C$18:$E$18)-$E$21-$D$20-$C$19 -> 0
A23: B- | B23: 28% GST on above | C23: =+$C$22*28% -> 0 | L23: =+L18+L16 -> 106.2
A25: (1+2) | B25: Total of parts after Dep & WITHOUT GST | C25: =+C22+C15 -> 0
B27: Labour without GST | C27: 0
B28: Painting Without GST | C28: 0
B29: Less : Dep on Painting charges @ 12.5% | C29: =+C28*12.5% -> 0
B30: Total (Labour + Painting) without GST | C30: =+C27+C28-C29 -> 0
A31: C- | B31: 18% GST on (Labour + Paint) above | C31: =+C30*18% -> 0
A33: A+B+C | B33: Total GST | C33: =+C16+C23+C31 -> 0
I34: =46.8+72.65 -> 119.45
B35: Add Towing | C35: 0 | I35: =+I34*28% -> 33.446
B36: Less Salvage | C36: 0
B37: Less Excess Clause | C37: 1000
B39: NET PAYABLE | C39: =ROUND((C25+C33+C35+C30-C36-C37),0) -> -1000
